
9/17/2019 10:10:57 AM
------------------------------------------------------------------------------------------------
Controller Name :- Requisition
Action Method Name :- Index
------------------------------------------------------------------------------------------------
Microsoft.AspNetCore.Mvc.Filters.ExceptionContext
Message ---
{0}Invalid column name 'JobTitle'.
Invalid column name 'Unit'.
Source ---
{0}Core .Net SqlClient Data Provider
StackTrace ---
{0}   at System.Data.SqlClient.SqlCommand.<>c.<ExecuteDbDataReaderAsync>b__122_0(Task`1 result)
   at System.Threading.Tasks.ContinuationResultTaskFromResultTask`2.InnerInvoke()
   at System.Threading.ExecutionContext.RunInternal(ExecutionContext executionContext, ContextCallback callback, Object state)
--- End of stack trace from previous location where exception was thrown ---
   at System.Threading.Tasks.Task.ExecuteWithThreadLocal(Task& currentTaskSlot)
--- End of stack trace from previous location where exception was thrown ---
   at Microsoft.EntityFrameworkCore.Storage.Internal.RelationalCommand.ExecuteAsync(IRelationalConnection connection, DbCommandMethod executeMethod, IReadOnlyDictionary`2 parameterValues, CancellationToken cancellationToken)
   at Microsoft.EntityFrameworkCore.Query.Internal.AsyncQueryingEnumerable`1.AsyncEnumerator.BufferlessMoveNext(DbContext _, Boolean buffer, CancellationToken cancellationToken)
   at Microsoft.EntityFrameworkCore.SqlServer.Storage.Internal.SqlServerExecutionStrategy.ExecuteAsync[TState,TResult](TState state, Func`4 operation, Func`4 verifySucceeded, CancellationToken cancellationToken)
   at Microsoft.EntityFrameworkCore.Query.Internal.AsyncQueryingEnumerable`1.AsyncEnumerator.MoveNext(CancellationToken cancellationToken)
   at Microsoft.EntityFrameworkCore.Query.Internal.AsyncLinqOperatorProvider.AsyncSelectEnumerable`2.AsyncSelectEnumerator.MoveNext(CancellationToken cancellationToken)
   at System.Linq.AsyncEnumerable.SelectEnumerableAsyncIterator`2.MoveNextCore(CancellationToken cancellationToken) in D:\a\1\s\Ix.NET\Source\System.Interactive.Async\Select.cs:line 106
   at System.Linq.AsyncEnumerable.AsyncIterator`1.MoveNext(CancellationToken cancellationToken) in D:\a\1\s\Ix.NET\Source\System.Interactive.Async\AsyncIterator.cs:line 98
   at Microsoft.EntityFrameworkCore.Query.Internal.AsyncLinqOperatorProvider.ExceptionInterceptor`1.EnumeratorExceptionInterceptor.MoveNext(CancellationToken cancellationToken)
   at System.Linq.AsyncEnumerable.Aggregate_[TSource,TAccumulate,TResult](IAsyncEnumerable`1 source, TAccumulate seed, Func`3 accumulator, Func`2 resultSelector, CancellationToken cancellationToken) in D:\a\1\s\Ix.NET\Source\System.Interactive.Async\Aggregate.cs:line 120
   at RequisitionManagement.Repository.PermissionRepo.RequisitionRepository.GetRequisitionsByUserAsync() in C:\Users\User\Source\Repos\CyberspaceRequisition\RequisitionManagement.Repository\Repos\RequisitionRepository.cs:line 66
   at RequisitionManagement.Web.Controllers.RequisitionController.Index() in C:\Users\User\Source\Repos\CyberspaceRequisition\RequisitionManagement.Web\Controllers\RequisitionController.cs:line 61
   at Microsoft.AspNetCore.Mvc.Internal.ActionMethodExecutor.TaskOfIActionResultExecutor.Execute(IActionResultTypeMapper mapper, ObjectMethodExecutor executor, Object controller, Object[] arguments)
   at System.Threading.Tasks.ValueTask`1.get_Result()
   at Microsoft.AspNetCore.Mvc.Internal.ControllerActionInvoker.InvokeActionMethodAsync()
   at Microsoft.AspNetCore.Mvc.Internal.ControllerActionInvoker.InvokeNextActionFilterAsync()
   at Microsoft.AspNetCore.Mvc.Internal.ControllerActionInvoker.Rethrow(ActionExecutedContext context)
   at Microsoft.AspNetCore.Mvc.Internal.ControllerActionInvoker.Next(State& next, Scope& scope, Object& state, Boolean& isCompleted)
   at Microsoft.AspNetCore.Mvc.Internal.ControllerActionInvoker.InvokeInnerFilterAsync()
   at Microsoft.AspNetCore.Mvc.Internal.ResourceInvoker.InvokeNextExceptionFilterAsync()
TargetSite ---
{0}System.Data.Common.DbDataReader <ExecuteDbDataReaderAsync>b__122_0(System.Threading.Tasks.Task`1[System.Data.SqlClient.SqlDataReader])


9/17/2019 10:11:07 AM
------------------------------------------------------------------------------------------------
Controller Name :- Requisition
Action Method Name :- Index
------------------------------------------------------------------------------------------------
Microsoft.AspNetCore.Mvc.Filters.ExceptionContext
Message ---
{0}Invalid column name 'JobTitle'.
Invalid column name 'Unit'.
Source ---
{0}Core .Net SqlClient Data Provider
StackTrace ---
{0}   at System.Data.SqlClient.SqlCommand.<>c.<ExecuteDbDataReaderAsync>b__122_0(Task`1 result)
   at System.Threading.Tasks.ContinuationResultTaskFromResultTask`2.InnerInvoke()
   at System.Threading.ExecutionContext.RunInternal(ExecutionContext executionContext, ContextCallback callback, Object state)
--- End of stack trace from previous location where exception was thrown ---
   at System.Threading.Tasks.Task.ExecuteWithThreadLocal(Task& currentTaskSlot)
--- End of stack trace from previous location where exception was thrown ---
   at Microsoft.EntityFrameworkCore.Storage.Internal.RelationalCommand.ExecuteAsync(IRelationalConnection connection, DbCommandMethod executeMethod, IReadOnlyDictionary`2 parameterValues, CancellationToken cancellationToken)
   at Microsoft.EntityFrameworkCore.Query.Internal.AsyncQueryingEnumerable`1.AsyncEnumerator.BufferlessMoveNext(DbContext _, Boolean buffer, CancellationToken cancellationToken)
   at Microsoft.EntityFrameworkCore.SqlServer.Storage.Internal.SqlServerExecutionStrategy.ExecuteAsync[TState,TResult](TState state, Func`4 operation, Func`4 verifySucceeded, CancellationToken cancellationToken)
   at Microsoft.EntityFrameworkCore.Query.Internal.AsyncQueryingEnumerable`1.AsyncEnumerator.MoveNext(CancellationToken cancellationToken)
   at Microsoft.EntityFrameworkCore.Query.Internal.AsyncLinqOperatorProvider.AsyncSelectEnumerable`2.AsyncSelectEnumerator.MoveNext(CancellationToken cancellationToken)
   at System.Linq.AsyncEnumerable.SelectEnumerableAsyncIterator`2.MoveNextCore(CancellationToken cancellationToken) in D:\a\1\s\Ix.NET\Source\System.Interactive.Async\Select.cs:line 106
   at System.Linq.AsyncEnumerable.AsyncIterator`1.MoveNext(CancellationToken cancellationToken) in D:\a\1\s\Ix.NET\Source\System.Interactive.Async\AsyncIterator.cs:line 98
   at Microsoft.EntityFrameworkCore.Query.Internal.AsyncLinqOperatorProvider.ExceptionInterceptor`1.EnumeratorExceptionInterceptor.MoveNext(CancellationToken cancellationToken)
   at System.Linq.AsyncEnumerable.Aggregate_[TSource,TAccumulate,TResult](IAsyncEnumerable`1 source, TAccumulate seed, Func`3 accumulator, Func`2 resultSelector, CancellationToken cancellationToken) in D:\a\1\s\Ix.NET\Source\System.Interactive.Async\Aggregate.cs:line 120
   at RequisitionManagement.Repository.PermissionRepo.RequisitionRepository.GetRequisitionsByUserAsync() in C:\Users\User\Source\Repos\CyberspaceRequisition\RequisitionManagement.Repository\Repos\RequisitionRepository.cs:line 66
   at RequisitionManagement.Web.Controllers.RequisitionController.Index() in C:\Users\User\Source\Repos\CyberspaceRequisition\RequisitionManagement.Web\Controllers\RequisitionController.cs:line 61
   at Microsoft.AspNetCore.Mvc.Internal.ActionMethodExecutor.TaskOfIActionResultExecutor.Execute(IActionResultTypeMapper mapper, ObjectMethodExecutor executor, Object controller, Object[] arguments)
   at System.Threading.Tasks.ValueTask`1.get_Result()
   at Microsoft.AspNetCore.Mvc.Internal.ControllerActionInvoker.InvokeActionMethodAsync()
   at Microsoft.AspNetCore.Mvc.Internal.ControllerActionInvoker.InvokeNextActionFilterAsync()
   at Microsoft.AspNetCore.Mvc.Internal.ControllerActionInvoker.Rethrow(ActionExecutedContext context)
   at Microsoft.AspNetCore.Mvc.Internal.ControllerActionInvoker.Next(State& next, Scope& scope, Object& state, Boolean& isCompleted)
   at Microsoft.AspNetCore.Mvc.Internal.ControllerActionInvoker.InvokeInnerFilterAsync()
   at Microsoft.AspNetCore.Mvc.Internal.ResourceInvoker.InvokeNextExceptionFilterAsync()
TargetSite ---
{0}System.Data.Common.DbDataReader <ExecuteDbDataReaderAsync>b__122_0(System.Threading.Tasks.Task`1[System.Data.SqlClient.SqlDataReader])


9/17/2019 10:11:19 AM
------------------------------------------------------------------------------------------------
Controller Name :- Requisition
Action Method Name :- Index
------------------------------------------------------------------------------------------------
Microsoft.AspNetCore.Mvc.Filters.ExceptionContext
Message ---
{0}A second operation started on this context before a previous operation completed. This is usually caused by different threads using the same instance of DbContext, however instance members are not guaranteed to be thread safe. This could also be caused by a nested query being evaluated on the client, if this is the case rewrite the query avoiding nested invocations.
Source ---
{0}Microsoft.EntityFrameworkCore
StackTrace ---
{0}   at Microsoft.EntityFrameworkCore.Internal.ConcurrencyDetector.EnterCriticalSection()
   at Microsoft.EntityFrameworkCore.Internal.ConcurrencyDetector.EnterCriticalSectionAsync(CancellationToken cancellationToken)
   at Microsoft.EntityFrameworkCore.Query.Internal.AsyncLinqOperatorProvider.ExceptionInterceptor`1.EnumeratorExceptionInterceptor.MoveNext(CancellationToken cancellationToken)
   at System.Linq.AsyncEnumerable.Aggregate_[TSource,TAccumulate,TResult](IAsyncEnumerable`1 source, TAccumulate seed, Func`3 accumulator, Func`2 resultSelector, CancellationToken cancellationToken) in D:\a\1\s\Ix.NET\Source\System.Interactive.Async\Aggregate.cs:line 120
   at RequisitionManagement.Repository.PermissionRepo.RequisitionRepository.GetRequisitionsByUserAsync() in C:\Users\User\Source\Repos\CyberspaceRequisition\RequisitionManagement.Repository\Repos\RequisitionRepository.cs:line 66
   at RequisitionManagement.Web.Controllers.RequisitionController.Index() in C:\Users\User\Source\Repos\CyberspaceRequisition\RequisitionManagement.Web\Controllers\RequisitionController.cs:line 61
   at Microsoft.AspNetCore.Mvc.Internal.ActionMethodExecutor.TaskOfIActionResultExecutor.Execute(IActionResultTypeMapper mapper, ObjectMethodExecutor executor, Object controller, Object[] arguments)
   at System.Threading.Tasks.ValueTask`1.get_Result()
   at Microsoft.AspNetCore.Mvc.Internal.ControllerActionInvoker.InvokeActionMethodAsync()
   at Microsoft.AspNetCore.Mvc.Internal.ControllerActionInvoker.InvokeNextActionFilterAsync()
   at Microsoft.AspNetCore.Mvc.Internal.ControllerActionInvoker.Rethrow(ActionExecutedContext context)
   at Microsoft.AspNetCore.Mvc.Internal.ControllerActionInvoker.Next(State& next, Scope& scope, Object& state, Boolean& isCompleted)
   at Microsoft.AspNetCore.Mvc.Internal.ControllerActionInvoker.InvokeInnerFilterAsync()
   at Microsoft.AspNetCore.Mvc.Internal.ResourceInvoker.InvokeNextExceptionFilterAsync()
TargetSite ---
{0}System.IDisposable EnterCriticalSection()


9/17/2019 10:11:31 AM
------------------------------------------------------------------------------------------------
Controller Name :- Approval
Action Method Name :- Index
------------------------------------------------------------------------------------------------
Microsoft.AspNetCore.Mvc.Filters.ExceptionContext
Message ---
{0}Invalid column name 'JobTitle'.
Invalid column name 'Unit'.
Source ---
{0}Core .Net SqlClient Data Provider
StackTrace ---
{0}   at System.Data.SqlClient.SqlCommand.<>c.<ExecuteDbDataReaderAsync>b__122_0(Task`1 result)
   at System.Threading.Tasks.ContinuationResultTaskFromResultTask`2.InnerInvoke()
   at System.Threading.ExecutionContext.RunInternal(ExecutionContext executionContext, ContextCallback callback, Object state)
--- End of stack trace from previous location where exception was thrown ---
   at System.Threading.Tasks.Task.ExecuteWithThreadLocal(Task& currentTaskSlot)
--- End of stack trace from previous location where exception was thrown ---
   at Microsoft.EntityFrameworkCore.Storage.Internal.RelationalCommand.ExecuteAsync(IRelationalConnection connection, DbCommandMethod executeMethod, IReadOnlyDictionary`2 parameterValues, CancellationToken cancellationToken)
   at Microsoft.EntityFrameworkCore.Query.Internal.AsyncQueryingEnumerable`1.AsyncEnumerator.BufferlessMoveNext(DbContext _, Boolean buffer, CancellationToken cancellationToken)
   at Microsoft.EntityFrameworkCore.SqlServer.Storage.Internal.SqlServerExecutionStrategy.ExecuteAsync[TState,TResult](TState state, Func`4 operation, Func`4 verifySucceeded, CancellationToken cancellationToken)
   at Microsoft.EntityFrameworkCore.Query.Internal.AsyncQueryingEnumerable`1.AsyncEnumerator.MoveNext(CancellationToken cancellationToken)
   at Microsoft.EntityFrameworkCore.Query.Internal.AsyncLinqOperatorProvider.AsyncSelectEnumerable`2.AsyncSelectEnumerator.MoveNext(CancellationToken cancellationToken)
   at System.Linq.AsyncEnumerable.SelectEnumerableAsyncIterator`2.MoveNextCore(CancellationToken cancellationToken) in D:\a\1\s\Ix.NET\Source\System.Interactive.Async\Select.cs:line 106
   at System.Linq.AsyncEnumerable.AsyncIterator`1.MoveNext(CancellationToken cancellationToken) in D:\a\1\s\Ix.NET\Source\System.Interactive.Async\AsyncIterator.cs:line 98
   at Microsoft.EntityFrameworkCore.Query.Internal.AsyncLinqOperatorProvider.ExceptionInterceptor`1.EnumeratorExceptionInterceptor.MoveNext(CancellationToken cancellationToken)
   at System.Linq.AsyncEnumerable.Aggregate_[TSource,TAccumulate,TResult](IAsyncEnumerable`1 source, TAccumulate seed, Func`3 accumulator, Func`2 resultSelector, CancellationToken cancellationToken) in D:\a\1\s\Ix.NET\Source\System.Interactive.Async\Aggregate.cs:line 120
   at RequisitionManagement.Repository.ApprovalRepo.RfqApprovalRepository.GetPendingApprovalAsync() in C:\Users\User\Source\Repos\CyberspaceRequisition\RequisitionManagement.Repository\ApprovalRepo\ApprovalRepository.cs:line 84
   at RequisitionManagement.Web.Controllers.ApprovalController.Index() in C:\Users\User\Source\Repos\CyberspaceRequisition\RequisitionManagement.Web\Controllers\ApprovalController.cs:line 64
   at Microsoft.AspNetCore.Mvc.Internal.ActionMethodExecutor.TaskOfIActionResultExecutor.Execute(IActionResultTypeMapper mapper, ObjectMethodExecutor executor, Object controller, Object[] arguments)
   at System.Threading.Tasks.ValueTask`1.get_Result()
   at Microsoft.AspNetCore.Mvc.Internal.ControllerActionInvoker.InvokeActionMethodAsync()
   at Microsoft.AspNetCore.Mvc.Internal.ControllerActionInvoker.InvokeNextActionFilterAsync()
   at Microsoft.AspNetCore.Mvc.Internal.ControllerActionInvoker.Rethrow(ActionExecutedContext context)
   at Microsoft.AspNetCore.Mvc.Internal.ControllerActionInvoker.Next(State& next, Scope& scope, Object& state, Boolean& isCompleted)
   at Microsoft.AspNetCore.Mvc.Internal.ControllerActionInvoker.InvokeInnerFilterAsync()
   at Microsoft.AspNetCore.Mvc.Internal.ResourceInvoker.InvokeNextExceptionFilterAsync()
TargetSite ---
{0}System.Data.Common.DbDataReader <ExecuteDbDataReaderAsync>b__122_0(System.Threading.Tasks.Task`1[System.Data.SqlClient.SqlDataReader])


9/17/2019 10:39:01 AM
------------------------------------------------------------------------------------------------
Controller Name :- Account
Action Method Name :- AssignUserRole
------------------------------------------------------------------------------------------------
Microsoft.AspNetCore.Mvc.Filters.ExceptionContext
Message ---
{0}A second operation started on this context before a previous operation completed. This is usually caused by different threads using the same instance of DbContext, however instance members are not guaranteed to be thread safe. This could also be caused by a nested query being evaluated on the client, if this is the case rewrite the query avoiding nested invocations.
Source ---
{0}RequisitionManagement.Web
StackTrace ---
{0}   at RequisitionManagement.Web.Controllers.AccountController.AssignUserRole() in C:\Users\User\Source\Repos\CyberspaceRequisition\RequisitionManagement.Web\Controllers\AccountController.cs:line 300
   at Microsoft.AspNetCore.Mvc.Internal.ActionMethodExecutor.TaskOfIActionResultExecutor.Execute(IActionResultTypeMapper mapper, ObjectMethodExecutor executor, Object controller, Object[] arguments)
   at System.Threading.Tasks.ValueTask`1.get_Result()
   at Microsoft.AspNetCore.Mvc.Internal.ControllerActionInvoker.InvokeActionMethodAsync()
   at Microsoft.AspNetCore.Mvc.Internal.ControllerActionInvoker.InvokeNextActionFilterAsync()
   at Microsoft.AspNetCore.Mvc.Internal.ControllerActionInvoker.Rethrow(ActionExecutedContext context)
   at Microsoft.AspNetCore.Mvc.Internal.ControllerActionInvoker.Next(State& next, Scope& scope, Object& state, Boolean& isCompleted)
   at Microsoft.AspNetCore.Mvc.Internal.ControllerActionInvoker.InvokeInnerFilterAsync()
   at Microsoft.AspNetCore.Mvc.Internal.ResourceInvoker.InvokeNextExceptionFilterAsync()
TargetSite ---
{0}Void MoveNext()


9/17/2019 10:39:07 AM
------------------------------------------------------------------------------------------------
Controller Name :- Account
Action Method Name :- AssignUserRole
------------------------------------------------------------------------------------------------
Microsoft.AspNetCore.Mvc.Filters.ExceptionContext
Message ---
{0}A second operation started on this context before a previous operation completed. This is usually caused by different threads using the same instance of DbContext, however instance members are not guaranteed to be thread safe. This could also be caused by a nested query being evaluated on the client, if this is the case rewrite the query avoiding nested invocations.
Source ---
{0}RequisitionManagement.Web
StackTrace ---
{0}   at RequisitionManagement.Web.Controllers.AccountController.AssignUserRole() in C:\Users\User\Source\Repos\CyberspaceRequisition\RequisitionManagement.Web\Controllers\AccountController.cs:line 300
   at Microsoft.AspNetCore.Mvc.Internal.ActionMethodExecutor.TaskOfIActionResultExecutor.Execute(IActionResultTypeMapper mapper, ObjectMethodExecutor executor, Object controller, Object[] arguments)
   at System.Threading.Tasks.ValueTask`1.get_Result()
   at Microsoft.AspNetCore.Mvc.Internal.ControllerActionInvoker.InvokeActionMethodAsync()
   at Microsoft.AspNetCore.Mvc.Internal.ControllerActionInvoker.InvokeNextActionFilterAsync()
   at Microsoft.AspNetCore.Mvc.Internal.ControllerActionInvoker.Rethrow(ActionExecutedContext context)
   at Microsoft.AspNetCore.Mvc.Internal.ControllerActionInvoker.Next(State& next, Scope& scope, Object& state, Boolean& isCompleted)
   at Microsoft.AspNetCore.Mvc.Internal.ControllerActionInvoker.InvokeInnerFilterAsync()
   at Microsoft.AspNetCore.Mvc.Internal.ResourceInvoker.InvokeNextExceptionFilterAsync()
TargetSite ---
{0}Void MoveNext()


9/17/2019 10:41:43 AM
------------------------------------------------------------------------------------------------
Controller Name :- Account
Action Method Name :- AssignUserRole
------------------------------------------------------------------------------------------------
Microsoft.AspNetCore.Mvc.Filters.ExceptionContext
Message ---
{0}A second operation started on this context before a previous operation completed. This is usually caused by different threads using the same instance of DbContext, however instance members are not guaranteed to be thread safe. This could also be caused by a nested query being evaluated on the client, if this is the case rewrite the query avoiding nested invocations.
Source ---
{0}RequisitionManagement.Web
StackTrace ---
{0}   at RequisitionManagement.Web.Controllers.AccountController.AssignUserRole() in C:\Users\User\Source\Repos\CyberspaceRequisition\RequisitionManagement.Web\Controllers\AccountController.cs:line 300
   at Microsoft.AspNetCore.Mvc.Internal.ActionMethodExecutor.TaskOfIActionResultExecutor.Execute(IActionResultTypeMapper mapper, ObjectMethodExecutor executor, Object controller, Object[] arguments)
   at System.Threading.Tasks.ValueTask`1.get_Result()
   at Microsoft.AspNetCore.Mvc.Internal.ControllerActionInvoker.InvokeActionMethodAsync()
   at Microsoft.AspNetCore.Mvc.Internal.ControllerActionInvoker.InvokeNextActionFilterAsync()
   at Microsoft.AspNetCore.Mvc.Internal.ControllerActionInvoker.Rethrow(ActionExecutedContext context)
   at Microsoft.AspNetCore.Mvc.Internal.ControllerActionInvoker.Next(State& next, Scope& scope, Object& state, Boolean& isCompleted)
   at Microsoft.AspNetCore.Mvc.Internal.ControllerActionInvoker.InvokeInnerFilterAsync()
   at Microsoft.AspNetCore.Mvc.Internal.ResourceInvoker.InvokeNextExceptionFilterAsync()
TargetSite ---
{0}Void MoveNext()


9/17/2019 10:43:16 AM
------------------------------------------------------------------------------------------------
Controller Name :- Account
Action Method Name :- AssignUserRole
------------------------------------------------------------------------------------------------
Microsoft.AspNetCore.Mvc.Filters.ExceptionContext
Message ---
{0}A second operation started on this context before a previous operation completed. This is usually caused by different threads using the same instance of DbContext, however instance members are not guaranteed to be thread safe. This could also be caused by a nested query being evaluated on the client, if this is the case rewrite the query avoiding nested invocations.
Source ---
{0}RequisitionManagement.Web
StackTrace ---
{0}   at RequisitionManagement.Web.Controllers.AccountController.AssignUserRole() in C:\Users\User\Source\Repos\CyberspaceRequisition\RequisitionManagement.Web\Controllers\AccountController.cs:line 300
   at Microsoft.AspNetCore.Mvc.Internal.ActionMethodExecutor.TaskOfIActionResultExecutor.Execute(IActionResultTypeMapper mapper, ObjectMethodExecutor executor, Object controller, Object[] arguments)
   at System.Threading.Tasks.ValueTask`1.get_Result()
   at Microsoft.AspNetCore.Mvc.Internal.ControllerActionInvoker.InvokeActionMethodAsync()
   at Microsoft.AspNetCore.Mvc.Internal.ControllerActionInvoker.InvokeNextActionFilterAsync()
   at Microsoft.AspNetCore.Mvc.Internal.ControllerActionInvoker.Rethrow(ActionExecutedContext context)
   at Microsoft.AspNetCore.Mvc.Internal.ControllerActionInvoker.Next(State& next, Scope& scope, Object& state, Boolean& isCompleted)
   at Microsoft.AspNetCore.Mvc.Internal.ControllerActionInvoker.InvokeInnerFilterAsync()
   at Microsoft.AspNetCore.Mvc.Internal.ResourceInvoker.InvokeNextExceptionFilterAsync()
TargetSite ---
{0}Void MoveNext()


9/17/2019 10:56:43 AM
------------------------------------------------------------------------------------------------
Controller Name :- Account
Action Method Name :- AssignUserRole
------------------------------------------------------------------------------------------------
Microsoft.AspNetCore.Mvc.Filters.ExceptionContext
Message ---
{0}A second operation started on this context before a previous operation completed. This is usually caused by different threads using the same instance of DbContext, however instance members are not guaranteed to be thread safe. This could also be caused by a nested query being evaluated on the client, if this is the case rewrite the query avoiding nested invocations.
Source ---
{0}RequisitionManagement.Web
StackTrace ---
{0}   at RequisitionManagement.Web.Controllers.AccountController.AssignUserRole() in C:\Users\User\Source\Repos\CyberspaceRequisition\RequisitionManagement.Web\Controllers\AccountController.cs:line 300
   at Microsoft.AspNetCore.Mvc.Internal.ActionMethodExecutor.TaskOfIActionResultExecutor.Execute(IActionResultTypeMapper mapper, ObjectMethodExecutor executor, Object controller, Object[] arguments)
   at System.Threading.Tasks.ValueTask`1.get_Result()
   at Microsoft.AspNetCore.Mvc.Internal.ControllerActionInvoker.InvokeActionMethodAsync()
   at Microsoft.AspNetCore.Mvc.Internal.ControllerActionInvoker.InvokeNextActionFilterAsync()
   at Microsoft.AspNetCore.Mvc.Internal.ControllerActionInvoker.Rethrow(ActionExecutedContext context)
   at Microsoft.AspNetCore.Mvc.Internal.ControllerActionInvoker.Next(State& next, Scope& scope, Object& state, Boolean& isCompleted)
   at Microsoft.AspNetCore.Mvc.Internal.ControllerActionInvoker.InvokeInnerFilterAsync()
   at Microsoft.AspNetCore.Mvc.Internal.ResourceInvoker.InvokeNextExceptionFilterAsync()
TargetSite ---
{0}Void MoveNext()


9/17/2019 10:56:51 AM
------------------------------------------------------------------------------------------------
Controller Name :- Account
Action Method Name :- AssignUserRole
------------------------------------------------------------------------------------------------
Microsoft.AspNetCore.Mvc.Filters.ExceptionContext
Message ---
{0}A second operation started on this context before a previous operation completed. This is usually caused by different threads using the same instance of DbContext, however instance members are not guaranteed to be thread safe. This could also be caused by a nested query being evaluated on the client, if this is the case rewrite the query avoiding nested invocations.
Source ---
{0}RequisitionManagement.Web
StackTrace ---
{0}   at RequisitionManagement.Web.Controllers.AccountController.AssignUserRole() in C:\Users\User\Source\Repos\CyberspaceRequisition\RequisitionManagement.Web\Controllers\AccountController.cs:line 300
   at Microsoft.AspNetCore.Mvc.Internal.ActionMethodExecutor.TaskOfIActionResultExecutor.Execute(IActionResultTypeMapper mapper, ObjectMethodExecutor executor, Object controller, Object[] arguments)
   at System.Threading.Tasks.ValueTask`1.get_Result()
   at Microsoft.AspNetCore.Mvc.Internal.ControllerActionInvoker.InvokeActionMethodAsync()
   at Microsoft.AspNetCore.Mvc.Internal.ControllerActionInvoker.InvokeNextActionFilterAsync()
   at Microsoft.AspNetCore.Mvc.Internal.ControllerActionInvoker.Rethrow(ActionExecutedContext context)
   at Microsoft.AspNetCore.Mvc.Internal.ControllerActionInvoker.Next(State& next, Scope& scope, Object& state, Boolean& isCompleted)
   at Microsoft.AspNetCore.Mvc.Internal.ControllerActionInvoker.InvokeInnerFilterAsync()
   at Microsoft.AspNetCore.Mvc.Internal.ResourceInvoker.InvokeNextExceptionFilterAsync()
TargetSite ---
{0}Void MoveNext()


9/17/2019 10:57:12 AM
------------------------------------------------------------------------------------------------
Controller Name :- Account
Action Method Name :- AssignUserRole
------------------------------------------------------------------------------------------------
Microsoft.AspNetCore.Mvc.Filters.ExceptionContext
Message ---
{0}A second operation started on this context before a previous operation completed. This is usually caused by different threads using the same instance of DbContext, however instance members are not guaranteed to be thread safe. This could also be caused by a nested query being evaluated on the client, if this is the case rewrite the query avoiding nested invocations.
Source ---
{0}RequisitionManagement.Web
StackTrace ---
{0}   at RequisitionManagement.Web.Controllers.AccountController.AssignUserRole() in C:\Users\User\Source\Repos\CyberspaceRequisition\RequisitionManagement.Web\Controllers\AccountController.cs:line 300
   at Microsoft.AspNetCore.Mvc.Internal.ActionMethodExecutor.TaskOfIActionResultExecutor.Execute(IActionResultTypeMapper mapper, ObjectMethodExecutor executor, Object controller, Object[] arguments)
   at System.Threading.Tasks.ValueTask`1.get_Result()
   at Microsoft.AspNetCore.Mvc.Internal.ControllerActionInvoker.InvokeActionMethodAsync()
   at Microsoft.AspNetCore.Mvc.Internal.ControllerActionInvoker.InvokeNextActionFilterAsync()
   at Microsoft.AspNetCore.Mvc.Internal.ControllerActionInvoker.Rethrow(ActionExecutedContext context)
   at Microsoft.AspNetCore.Mvc.Internal.ControllerActionInvoker.Next(State& next, Scope& scope, Object& state, Boolean& isCompleted)
   at Microsoft.AspNetCore.Mvc.Internal.ControllerActionInvoker.InvokeInnerFilterAsync()
   at Microsoft.AspNetCore.Mvc.Internal.ResourceInvoker.InvokeNextExceptionFilterAsync()
TargetSite ---
{0}Void MoveNext()


9/17/2019 11:19:10 AM
------------------------------------------------------------------------------------------------
Controller Name :- Account
Action Method Name :- UserRoles
------------------------------------------------------------------------------------------------
Microsoft.AspNetCore.Mvc.Filters.ExceptionContext
Message ---
{0}A second operation started on this context before a previous operation completed. This is usually caused by different threads using the same instance of DbContext, however instance members are not guaranteed to be thread safe. This could also be caused by a nested query being evaluated on the client, if this is the case rewrite the query avoiding nested invocations.
Source ---
{0}Microsoft.EntityFrameworkCore
StackTrace ---
{0}   at Microsoft.EntityFrameworkCore.Internal.ConcurrencyDetector.EnterCriticalSection()
   at Microsoft.EntityFrameworkCore.Internal.ConcurrencyDetector.EnterCriticalSectionAsync(CancellationToken cancellationToken)
   at Microsoft.EntityFrameworkCore.Query.Internal.AsyncLinqOperatorProvider.ExceptionInterceptor`1.EnumeratorExceptionInterceptor.MoveNext(CancellationToken cancellationToken)
   at System.Linq.AsyncEnumerable.Aggregate_[TSource,TAccumulate,TResult](IAsyncEnumerable`1 source, TAccumulate seed, Func`3 accumulator, Func`2 resultSelector, CancellationToken cancellationToken) in D:\a\1\s\Ix.NET\Source\System.Interactive.Async\Aggregate.cs:line 120
   at RequisitionManagement.Repository.AccountRepo.AccountManager.GetUsers() in C:\Users\User\Source\Repos\CyberspaceRequisition\RequisitionManagement.Repository\AccountRepo\AccountManager.cs:line 71
   at RequisitionManagement.Web.Controllers.AccountController.UserRoles() in C:\Users\User\Source\Repos\CyberspaceRequisition\RequisitionManagement.Web\Controllers\AccountController.cs:line 452
   at Microsoft.AspNetCore.Mvc.Internal.ActionMethodExecutor.TaskOfIActionResultExecutor.Execute(IActionResultTypeMapper mapper, ObjectMethodExecutor executor, Object controller, Object[] arguments)
   at System.Threading.Tasks.ValueTask`1.get_Result()
   at Microsoft.AspNetCore.Mvc.Internal.ControllerActionInvoker.InvokeActionMethodAsync()
   at Microsoft.AspNetCore.Mvc.Internal.ControllerActionInvoker.InvokeNextActionFilterAsync()
   at Microsoft.AspNetCore.Mvc.Internal.ControllerActionInvoker.Rethrow(ActionExecutedContext context)
   at Microsoft.AspNetCore.Mvc.Internal.ControllerActionInvoker.Next(State& next, Scope& scope, Object& state, Boolean& isCompleted)
   at Microsoft.AspNetCore.Mvc.Internal.ControllerActionInvoker.InvokeInnerFilterAsync()
   at Microsoft.AspNetCore.Mvc.Internal.ResourceInvoker.InvokeNextExceptionFilterAsync()
TargetSite ---
{0}System.IDisposable EnterCriticalSection()


9/17/2019 11:21:28 AM
------------------------------------------------------------------------------------------------
Controller Name :- Account
Action Method Name :- AssignUserRole
------------------------------------------------------------------------------------------------
Microsoft.AspNetCore.Mvc.Filters.ExceptionContext
Message ---
{0}A second operation started on this context before a previous operation completed. This is usually caused by different threads using the same instance of DbContext, however instance members are not guaranteed to be thread safe. This could also be caused by a nested query being evaluated on the client, if this is the case rewrite the query avoiding nested invocations.
Source ---
{0}RequisitionManagement.Web
StackTrace ---
{0}   at RequisitionManagement.Web.Controllers.AccountController.AssignUserRole() in C:\Users\User\Source\Repos\CyberspaceRequisition\RequisitionManagement.Web\Controllers\AccountController.cs:line 300
   at Microsoft.AspNetCore.Mvc.Internal.ActionMethodExecutor.TaskOfIActionResultExecutor.Execute(IActionResultTypeMapper mapper, ObjectMethodExecutor executor, Object controller, Object[] arguments)
   at System.Threading.Tasks.ValueTask`1.get_Result()
   at Microsoft.AspNetCore.Mvc.Internal.ControllerActionInvoker.InvokeActionMethodAsync()
   at Microsoft.AspNetCore.Mvc.Internal.ControllerActionInvoker.InvokeNextActionFilterAsync()
   at Microsoft.AspNetCore.Mvc.Internal.ControllerActionInvoker.Rethrow(ActionExecutedContext context)
   at Microsoft.AspNetCore.Mvc.Internal.ControllerActionInvoker.Next(State& next, Scope& scope, Object& state, Boolean& isCompleted)
   at Microsoft.AspNetCore.Mvc.Internal.ControllerActionInvoker.InvokeInnerFilterAsync()
   at Microsoft.AspNetCore.Mvc.Internal.ResourceInvoker.InvokeNextExceptionFilterAsync()
TargetSite ---
{0}Void MoveNext()


9/17/2019 11:29:03 AM
------------------------------------------------------------------------------------------------
Controller Name :- Account
Action Method Name :- UserRoles
------------------------------------------------------------------------------------------------
Microsoft.AspNetCore.Mvc.Filters.ExceptionContext
Message ---
{0}A second operation started on this context before a previous operation completed. This is usually caused by different threads using the same instance of DbContext, however instance members are not guaranteed to be thread safe. This could also be caused by a nested query being evaluated on the client, if this is the case rewrite the query avoiding nested invocations.
Source ---
{0}Microsoft.EntityFrameworkCore
StackTrace ---
{0}   at Microsoft.EntityFrameworkCore.Internal.ConcurrencyDetector.EnterCriticalSection()
   at Microsoft.EntityFrameworkCore.Internal.ConcurrencyDetector.EnterCriticalSectionAsync(CancellationToken cancellationToken)
   at Microsoft.EntityFrameworkCore.Query.Internal.AsyncLinqOperatorProvider.ExceptionInterceptor`1.EnumeratorExceptionInterceptor.MoveNext(CancellationToken cancellationToken)
   at System.Linq.AsyncEnumerable.Aggregate_[TSource,TAccumulate,TResult](IAsyncEnumerable`1 source, TAccumulate seed, Func`3 accumulator, Func`2 resultSelector, CancellationToken cancellationToken) in D:\a\1\s\Ix.NET\Source\System.Interactive.Async\Aggregate.cs:line 120
   at RequisitionManagement.Repository.AccountRepo.AccountManager.GetUsers() in C:\Users\User\Source\Repos\CyberspaceRequisition\RequisitionManagement.Repository\AccountRepo\AccountManager.cs:line 71
   at RequisitionManagement.Web.Controllers.AccountController.UserRoles() in C:\Users\User\Source\Repos\CyberspaceRequisition\RequisitionManagement.Web\Controllers\AccountController.cs:line 452
   at Microsoft.AspNetCore.Mvc.Internal.ActionMethodExecutor.TaskOfIActionResultExecutor.Execute(IActionResultTypeMapper mapper, ObjectMethodExecutor executor, Object controller, Object[] arguments)
   at System.Threading.Tasks.ValueTask`1.get_Result()
   at Microsoft.AspNetCore.Mvc.Internal.ControllerActionInvoker.InvokeActionMethodAsync()
   at Microsoft.AspNetCore.Mvc.Internal.ControllerActionInvoker.InvokeNextActionFilterAsync()
   at Microsoft.AspNetCore.Mvc.Internal.ControllerActionInvoker.Rethrow(ActionExecutedContext context)
   at Microsoft.AspNetCore.Mvc.Internal.ControllerActionInvoker.Next(State& next, Scope& scope, Object& state, Boolean& isCompleted)
   at Microsoft.AspNetCore.Mvc.Internal.ControllerActionInvoker.InvokeInnerFilterAsync()
   at Microsoft.AspNetCore.Mvc.Internal.ResourceInvoker.InvokeNextExceptionFilterAsync()
TargetSite ---
{0}System.IDisposable EnterCriticalSection()


9/17/2019 11:35:23 AM
------------------------------------------------------------------------------------------------
Controller Name :- Account
Action Method Name :- UserRoles
------------------------------------------------------------------------------------------------
Microsoft.AspNetCore.Mvc.Filters.ExceptionContext
Message ---
{0}A second operation started on this context before a previous operation completed. This is usually caused by different threads using the same instance of DbContext, however instance members are not guaranteed to be thread safe. This could also be caused by a nested query being evaluated on the client, if this is the case rewrite the query avoiding nested invocations.
Source ---
{0}Microsoft.EntityFrameworkCore
StackTrace ---
{0}   at Microsoft.EntityFrameworkCore.Internal.ConcurrencyDetector.EnterCriticalSection()
   at Microsoft.EntityFrameworkCore.Internal.ConcurrencyDetector.EnterCriticalSectionAsync(CancellationToken cancellationToken)
   at Microsoft.EntityFrameworkCore.Query.Internal.AsyncLinqOperatorProvider.ExceptionInterceptor`1.EnumeratorExceptionInterceptor.MoveNext(CancellationToken cancellationToken)
   at System.Linq.AsyncEnumerable.Aggregate_[TSource,TAccumulate,TResult](IAsyncEnumerable`1 source, TAccumulate seed, Func`3 accumulator, Func`2 resultSelector, CancellationToken cancellationToken) in D:\a\1\s\Ix.NET\Source\System.Interactive.Async\Aggregate.cs:line 120
   at RequisitionManagement.Repository.AccountRepo.AccountManager.GetUsers() in C:\Users\User\Source\Repos\CyberspaceRequisition\RequisitionManagement.Repository\AccountRepo\AccountManager.cs:line 71
   at RequisitionManagement.Web.Controllers.AccountController.UserRoles() in C:\Users\User\Source\Repos\CyberspaceRequisition\RequisitionManagement.Web\Controllers\AccountController.cs:line 452
   at Microsoft.AspNetCore.Mvc.Internal.ActionMethodExecutor.TaskOfIActionResultExecutor.Execute(IActionResultTypeMapper mapper, ObjectMethodExecutor executor, Object controller, Object[] arguments)
   at System.Threading.Tasks.ValueTask`1.get_Result()
   at Microsoft.AspNetCore.Mvc.Internal.ControllerActionInvoker.InvokeActionMethodAsync()
   at Microsoft.AspNetCore.Mvc.Internal.ControllerActionInvoker.InvokeNextActionFilterAsync()
   at Microsoft.AspNetCore.Mvc.Internal.ControllerActionInvoker.Rethrow(ActionExecutedContext context)
   at Microsoft.AspNetCore.Mvc.Internal.ControllerActionInvoker.Next(State& next, Scope& scope, Object& state, Boolean& isCompleted)
   at Microsoft.AspNetCore.Mvc.Internal.ControllerActionInvoker.InvokeInnerFilterAsync()
   at Microsoft.AspNetCore.Mvc.Internal.ResourceInvoker.InvokeNextExceptionFilterAsync()
TargetSite ---
{0}System.IDisposable EnterCriticalSection()


9/17/2019 11:39:54 AM
------------------------------------------------------------------------------------------------
Controller Name :- Account
Action Method Name :- AssignUserRole
------------------------------------------------------------------------------------------------
Microsoft.AspNetCore.Mvc.Filters.ExceptionContext
Message ---
{0}A second operation started on this context before a previous operation completed. This is usually caused by different threads using the same instance of DbContext, however instance members are not guaranteed to be thread safe. This could also be caused by a nested query being evaluated on the client, if this is the case rewrite the query avoiding nested invocations.
Source ---
{0}RequisitionManagement.Web
StackTrace ---
{0}   at RequisitionManagement.Web.Controllers.AccountController.AssignUserRole() in C:\Users\User\Source\Repos\CyberspaceRequisition\RequisitionManagement.Web\Controllers\AccountController.cs:line 300
   at Microsoft.AspNetCore.Mvc.Internal.ActionMethodExecutor.TaskOfIActionResultExecutor.Execute(IActionResultTypeMapper mapper, ObjectMethodExecutor executor, Object controller, Object[] arguments)
   at System.Threading.Tasks.ValueTask`1.get_Result()
   at Microsoft.AspNetCore.Mvc.Internal.ControllerActionInvoker.InvokeActionMethodAsync()
   at Microsoft.AspNetCore.Mvc.Internal.ControllerActionInvoker.InvokeNextActionFilterAsync()
   at Microsoft.AspNetCore.Mvc.Internal.ControllerActionInvoker.Rethrow(ActionExecutedContext context)
   at Microsoft.AspNetCore.Mvc.Internal.ControllerActionInvoker.Next(State& next, Scope& scope, Object& state, Boolean& isCompleted)
   at Microsoft.AspNetCore.Mvc.Internal.ControllerActionInvoker.InvokeInnerFilterAsync()
   at Microsoft.AspNetCore.Mvc.Internal.ResourceInvoker.InvokeNextExceptionFilterAsync()
TargetSite ---
{0}Void MoveNext()


9/17/2019 3:21:07 PM
------------------------------------------------------------------------------------------------
Controller Name :- Requisition
Action Method Name :- Create
------------------------------------------------------------------------------------------------
Microsoft.AspNetCore.Mvc.Filters.ExceptionContext
Message ---
{0}A network-related or instance-specific error occurred while establishing a connection to SQL Server. The server was not found or was not accessible. Verify that the instance name is correct and that SQL Server is configured to allow remote connections. (provider: Named Pipes Provider, error: 40 - Could not open a connection to SQL Server)
Source ---
{0}Core .Net SqlClient Data Provider
StackTrace ---
{0}   at System.Data.ProviderBase.DbConnectionPool.TryGetConnection(DbConnection owningObject, UInt32 waitForMultipleObjectsTimeout, Boolean allowCreate, Boolean onlyOneCheckConnection, DbConnectionOptions userOptions, DbConnectionInternal& connection)
   at System.Data.ProviderBase.DbConnectionPool.TryGetConnection(DbConnection owningObject, TaskCompletionSource`1 retry, DbConnectionOptions userOptions, DbConnectionInternal& connection)
   at System.Data.ProviderBase.DbConnectionFactory.TryGetConnection(DbConnection owningConnection, TaskCompletionSource`1 retry, DbConnectionOptions userOptions, DbConnectionInternal oldConnection, DbConnectionInternal& connection)
   at System.Data.ProviderBase.DbConnectionInternal.TryOpenConnectionInternal(DbConnection outerConnection, DbConnectionFactory connectionFactory, TaskCompletionSource`1 retry, DbConnectionOptions userOptions)
   at System.Data.ProviderBase.DbConnectionClosed.TryOpenConnection(DbConnection outerConnection, DbConnectionFactory connectionFactory, TaskCompletionSource`1 retry, DbConnectionOptions userOptions)
   at System.Data.SqlClient.SqlConnection.TryOpen(TaskCompletionSource`1 retry)
   at System.Data.SqlClient.SqlConnection.OpenAsync(CancellationToken cancellationToken)
--- End of stack trace from previous location where exception was thrown ---
   at Microsoft.EntityFrameworkCore.Storage.RelationalConnection.OpenDbConnectionAsync(Boolean errorsExpected, CancellationToken cancellationToken)
   at Microsoft.EntityFrameworkCore.Storage.RelationalConnection.OpenAsync(CancellationToken cancellationToken, Boolean errorsExpected)
   at Microsoft.EntityFrameworkCore.Query.Internal.AsyncQueryingEnumerable`1.AsyncEnumerator.BufferlessMoveNext(DbContext _, Boolean buffer, CancellationToken cancellationToken)
   at Microsoft.EntityFrameworkCore.SqlServer.Storage.Internal.SqlServerExecutionStrategy.ExecuteAsync[TState,TResult](TState state, Func`4 operation, Func`4 verifySucceeded, CancellationToken cancellationToken)
   at Microsoft.EntityFrameworkCore.Query.Internal.AsyncQueryingEnumerable`1.AsyncEnumerator.MoveNext(CancellationToken cancellationToken)
   at System.Linq.AsyncEnumerable.SelectEnumerableAsyncIterator`2.MoveNextCore(CancellationToken cancellationToken) in D:\a\1\s\Ix.NET\Source\System.Interactive.Async\Select.cs:line 106
   at System.Linq.AsyncEnumerable.AsyncIterator`1.MoveNext(CancellationToken cancellationToken) in D:\a\1\s\Ix.NET\Source\System.Interactive.Async\AsyncIterator.cs:line 98
   at Microsoft.EntityFrameworkCore.Query.Internal.AsyncLinqOperatorProvider.ExceptionInterceptor`1.EnumeratorExceptionInterceptor.MoveNext(CancellationToken cancellationToken)
   at System.Linq.AsyncEnumerable.Aggregate_[TSource,TAccumulate,TResult](IAsyncEnumerable`1 source, TAccumulate seed, Func`3 accumulator, Func`2 resultSelector, CancellationToken cancellationToken) in D:\a\1\s\Ix.NET\Source\System.Interactive.Async\Aggregate.cs:line 120
   at RequisitionManagement.Repository.PermissionRepo.ItemCategoryRepository.GetItemCategoryAsync() in C:\Users\User\Source\Repos\CyberspaceRequisition\RequisitionManagement.Repository\Repos\ItemCategoryRepository.cs:line 38
   at RequisitionManagement.Web.Controllers.RequisitionController.Create() in C:\Users\User\Source\Repos\CyberspaceRequisition\RequisitionManagement.Web\Controllers\RequisitionController.cs:line 113
   at Microsoft.AspNetCore.Mvc.Internal.ActionMethodExecutor.TaskOfIActionResultExecutor.Execute(IActionResultTypeMapper mapper, ObjectMethodExecutor executor, Object controller, Object[] arguments)
   at System.Threading.Tasks.ValueTask`1.get_Result()
   at Microsoft.AspNetCore.Mvc.Internal.ControllerActionInvoker.InvokeActionMethodAsync()
   at Microsoft.AspNetCore.Mvc.Internal.ControllerActionInvoker.InvokeNextActionFilterAsync()
   at Microsoft.AspNetCore.Mvc.Internal.ControllerActionInvoker.Rethrow(ActionExecutedContext context)
   at Microsoft.AspNetCore.Mvc.Internal.ControllerActionInvoker.Next(State& next, Scope& scope, Object& state, Boolean& isCompleted)
   at Microsoft.AspNetCore.Mvc.Internal.ControllerActionInvoker.InvokeInnerFilterAsync()
   at Microsoft.AspNetCore.Mvc.Internal.ResourceInvoker.InvokeNextExceptionFilterAsync()
TargetSite ---
{0}Boolean TryGetConnection(System.Data.Common.DbConnection, UInt32, Boolean, Boolean, System.Data.Common.DbConnectionOptions, System.Data.ProviderBase.DbConnectionInternal ByRef)
Inner Exception is {0}System.ComponentModel.Win32Exception (2): The system cannot find the file specified


9/17/2019 3:21:44 PM
------------------------------------------------------------------------------------------------
Controller Name :- Account
Action Method Name :- UserRoles
------------------------------------------------------------------------------------------------
Microsoft.AspNetCore.Mvc.Filters.ExceptionContext
Message ---
{0}A network-related or instance-specific error occurred while establishing a connection to SQL Server. The server was not found or was not accessible. Verify that the instance name is correct and that SQL Server is configured to allow remote connections. (provider: Named Pipes Provider, error: 40 - Could not open a connection to SQL Server)
Source ---
{0}Core .Net SqlClient Data Provider
StackTrace ---
{0}   at System.Data.ProviderBase.DbConnectionPool.TryGetConnection(DbConnection owningObject, UInt32 waitForMultipleObjectsTimeout, Boolean allowCreate, Boolean onlyOneCheckConnection, DbConnectionOptions userOptions, DbConnectionInternal& connection)
   at System.Data.ProviderBase.DbConnectionPool.TryGetConnection(DbConnection owningObject, TaskCompletionSource`1 retry, DbConnectionOptions userOptions, DbConnectionInternal& connection)
   at System.Data.ProviderBase.DbConnectionFactory.TryGetConnection(DbConnection owningConnection, TaskCompletionSource`1 retry, DbConnectionOptions userOptions, DbConnectionInternal oldConnection, DbConnectionInternal& connection)
   at System.Data.ProviderBase.DbConnectionInternal.TryOpenConnectionInternal(DbConnection outerConnection, DbConnectionFactory connectionFactory, TaskCompletionSource`1 retry, DbConnectionOptions userOptions)
   at System.Data.ProviderBase.DbConnectionClosed.TryOpenConnection(DbConnection outerConnection, DbConnectionFactory connectionFactory, TaskCompletionSource`1 retry, DbConnectionOptions userOptions)
   at System.Data.SqlClient.SqlConnection.TryOpen(TaskCompletionSource`1 retry)
   at System.Data.SqlClient.SqlConnection.OpenAsync(CancellationToken cancellationToken)
--- End of stack trace from previous location where exception was thrown ---
   at Microsoft.EntityFrameworkCore.Storage.RelationalConnection.OpenDbConnectionAsync(Boolean errorsExpected, CancellationToken cancellationToken)
   at Microsoft.EntityFrameworkCore.Storage.RelationalConnection.OpenAsync(CancellationToken cancellationToken, Boolean errorsExpected)
   at Microsoft.EntityFrameworkCore.Query.Internal.AsyncQueryingEnumerable`1.AsyncEnumerator.BufferlessMoveNext(DbContext _, Boolean buffer, CancellationToken cancellationToken)
   at Microsoft.EntityFrameworkCore.SqlServer.Storage.Internal.SqlServerExecutionStrategy.ExecuteAsync[TState,TResult](TState state, Func`4 operation, Func`4 verifySucceeded, CancellationToken cancellationToken)
   at Microsoft.EntityFrameworkCore.Query.Internal.AsyncQueryingEnumerable`1.AsyncEnumerator.MoveNext(CancellationToken cancellationToken)
   at System.Linq.AsyncEnumerable.SelectEnumerableAsyncIterator`2.MoveNextCore(CancellationToken cancellationToken) in D:\a\1\s\Ix.NET\Source\System.Interactive.Async\Select.cs:line 106
   at System.Linq.AsyncEnumerable.AsyncIterator`1.MoveNext(CancellationToken cancellationToken) in D:\a\1\s\Ix.NET\Source\System.Interactive.Async\AsyncIterator.cs:line 98
   at Microsoft.EntityFrameworkCore.Query.Internal.AsyncLinqOperatorProvider.ExceptionInterceptor`1.EnumeratorExceptionInterceptor.MoveNext(CancellationToken cancellationToken)
   at System.Linq.AsyncEnumerable.Aggregate_[TSource,TAccumulate,TResult](IAsyncEnumerable`1 source, TAccumulate seed, Func`3 accumulator, Func`2 resultSelector, CancellationToken cancellationToken) in D:\a\1\s\Ix.NET\Source\System.Interactive.Async\Aggregate.cs:line 120
   at RequisitionManagement.Repository.AccountRepo.AccountManager.GetUsers() in C:\Users\User\Source\Repos\CyberspaceRequisition\RequisitionManagement.Repository\AccountRepo\AccountManager.cs:line 71
   at RequisitionManagement.Web.Controllers.AccountController.UserRoles() in C:\Users\User\Source\Repos\CyberspaceRequisition\RequisitionManagement.Web\Controllers\AccountController.cs:line 452
   at Microsoft.AspNetCore.Mvc.Internal.ActionMethodExecutor.TaskOfIActionResultExecutor.Execute(IActionResultTypeMapper mapper, ObjectMethodExecutor executor, Object controller, Object[] arguments)
   at System.Threading.Tasks.ValueTask`1.get_Result()
   at Microsoft.AspNetCore.Mvc.Internal.ControllerActionInvoker.InvokeActionMethodAsync()
   at Microsoft.AspNetCore.Mvc.Internal.ControllerActionInvoker.InvokeNextActionFilterAsync()
   at Microsoft.AspNetCore.Mvc.Internal.ControllerActionInvoker.Rethrow(ActionExecutedContext context)
   at Microsoft.AspNetCore.Mvc.Internal.ControllerActionInvoker.Next(State& next, Scope& scope, Object& state, Boolean& isCompleted)
   at Microsoft.AspNetCore.Mvc.Internal.ControllerActionInvoker.InvokeInnerFilterAsync()
   at Microsoft.AspNetCore.Mvc.Internal.ResourceInvoker.InvokeNextExceptionFilterAsync()
TargetSite ---
{0}Boolean TryGetConnection(System.Data.Common.DbConnection, UInt32, Boolean, Boolean, System.Data.Common.DbConnectionOptions, System.Data.ProviderBase.DbConnectionInternal ByRef)
Inner Exception is {0}System.ComponentModel.Win32Exception (2): The system cannot find the file specified


9/17/2019 4:36:40 PM
------------------------------------------------------------------------------------------------
Controller Name :- Requisition
Action Method Name :- Create
------------------------------------------------------------------------------------------------
Microsoft.AspNetCore.Mvc.Filters.ExceptionContext
Message ---
{0}An exception was thrown while attempting to evaluate a LINQ query parameter expression. To show additional information call EnableSensitiveDataLogging() when overriding DbContext.OnConfiguring.
Source ---
{0}Microsoft.EntityFrameworkCore
StackTrace ---
{0}   at Microsoft.EntityFrameworkCore.Query.ExpressionVisitors.Internal.ParameterExtractingExpressionVisitor.Evaluate(Expression expression, String& parameterName)
   at Microsoft.EntityFrameworkCore.Query.ExpressionVisitors.Internal.ParameterExtractingExpressionVisitor.TryExtractParameter(Expression expression)
   at Microsoft.EntityFrameworkCore.Query.ExpressionVisitors.Internal.ParameterExtractingExpressionVisitor.VisitMethodCall(MethodCallExpression methodCallExpression)
   at System.Linq.Expressions.MethodCallExpression.Accept(ExpressionVisitor visitor)
   at System.Linq.Expressions.ExpressionVisitor.Visit(Expression node)
   at System.Linq.Expressions.ExpressionVisitor.VisitBinary(BinaryExpression node)
   at System.Linq.Expressions.BinaryExpression.Accept(ExpressionVisitor visitor)
   at System.Linq.Expressions.ExpressionVisitor.Visit(Expression node)
   at Microsoft.EntityFrameworkCore.Query.ExpressionVisitors.Internal.ParameterExtractingExpressionVisitor.VisitBinary(BinaryExpression binaryExpression)
   at System.Linq.Expressions.BinaryExpression.Accept(ExpressionVisitor visitor)
   at System.Linq.Expressions.ExpressionVisitor.Visit(Expression node)
   at System.Linq.Expressions.ExpressionVisitor.VisitLambda[T](Expression`1 node)
   at Microsoft.EntityFrameworkCore.Query.ExpressionVisitors.Internal.ParameterExtractingExpressionVisitor.VisitLambda[T](Expression`1 node)
   at System.Linq.Expressions.Expression`1.Accept(ExpressionVisitor visitor)
   at System.Linq.Expressions.ExpressionVisitor.Visit(Expression node)
   at System.Linq.Expressions.ExpressionVisitor.VisitUnary(UnaryExpression node)
   at Microsoft.EntityFrameworkCore.Query.ExpressionVisitors.Internal.ParameterExtractingExpressionVisitor.VisitUnary(UnaryExpression unaryExpression)
   at System.Linq.Expressions.UnaryExpression.Accept(ExpressionVisitor visitor)
   at System.Linq.Expressions.ExpressionVisitor.Visit(Expression node)
   at System.Dynamic.Utils.ExpressionVisitorUtils.VisitArguments(ExpressionVisitor visitor, IArgumentProvider nodes)
   at System.Linq.Expressions.ExpressionVisitor.VisitMethodCall(MethodCallExpression node)
   at Microsoft.EntityFrameworkCore.Query.ExpressionVisitors.Internal.ParameterExtractingExpressionVisitor.VisitMethodCall(MethodCallExpression methodCallExpression)
   at System.Linq.Expressions.MethodCallExpression.Accept(ExpressionVisitor visitor)
   at System.Linq.Expressions.ExpressionVisitor.Visit(Expression node)
   at Microsoft.EntityFrameworkCore.Query.ExpressionVisitors.Internal.ParameterExtractingExpressionVisitor.ExtractParameters(Expression expression)
   at Microsoft.EntityFrameworkCore.Query.Internal.QueryCompiler.ExecuteAsync[TResult](Expression query)
   at Microsoft.EntityFrameworkCore.Query.Internal.EntityQueryable`1.System.Collections.Generic.IAsyncEnumerable<TResult>.GetEnumerator()
   at System.Linq.AsyncEnumerable.Aggregate_[TSource,TAccumulate,TResult](IAsyncEnumerable`1 source, TAccumulate seed, Func`3 accumulator, Func`2 resultSelector, CancellationToken cancellationToken) in D:\a\1\s\Ix.NET\Source\System.Interactive.Async\Aggregate.cs:line 118
   at RequisitionManagement.Repository.ApprovalRepo.ApprovalConfigRepository.GetApprovalEmailByUnitAsync(String department, String unit) in C:\Users\User\Source\Repos\CyberspaceRequisition\RequisitionManagement.Repository\ApprovalRepo\ApprovalConfigRepository.cs:line 146
   at RequisitionManagement.Web.Controllers.RequisitionController.Create(RequisitionModel requisition) in C:\Users\User\Source\Repos\CyberspaceRequisition\RequisitionManagement.Web\Controllers\RequisitionController.cs:line 261
   at Microsoft.AspNetCore.Mvc.Internal.ActionMethodExecutor.TaskOfIActionResultExecutor.Execute(IActionResultTypeMapper mapper, ObjectMethodExecutor executor, Object controller, Object[] arguments)
   at System.Threading.Tasks.ValueTask`1.get_Result()
   at Microsoft.AspNetCore.Mvc.Internal.ControllerActionInvoker.InvokeActionMethodAsync()
   at Microsoft.AspNetCore.Mvc.Internal.ControllerActionInvoker.InvokeNextActionFilterAsync()
   at Microsoft.AspNetCore.Mvc.Internal.ControllerActionInvoker.Rethrow(ActionExecutedContext context)
   at Microsoft.AspNetCore.Mvc.Internal.ControllerActionInvoker.Next(State& next, Scope& scope, Object& state, Boolean& isCompleted)
   at Microsoft.AspNetCore.Mvc.Internal.ControllerActionInvoker.InvokeInnerFilterAsync()
   at Microsoft.AspNetCore.Mvc.Internal.ResourceInvoker.InvokeNextExceptionFilterAsync()
TargetSite ---
{0}System.Object Evaluate(System.Linq.Expressions.Expression, System.String ByRef)
Inner Exception is {0}System.NullReferenceException: Object reference not set to an instance of an object.
   at lambda_method(Closure )
   at Microsoft.EntityFrameworkCore.Query.ExpressionVisitors.Internal.ParameterExtractingExpressionVisitor.Evaluate(Expression expression, String& parameterName)

